<?xml version="1.0" ?>
<!-- =================================================================================== -->
<!-- |    This document was autogenerated by xacro from ur5_w_robotiq_85_gripper.urdf.xacro | -->
<!-- |    EDITING THIS FILE BY HAND IS NOT RECOMMENDED                                 | -->
<!-- =================================================================================== -->
<robot name="assembled_robot" xmlns:xacro="http://ros.org/wiki/xacro">
  <!-- THE ROBOT -->
  <!-- THE ROBOT -->
  <link name="world"/>
  <joint name="world_joint" type="fixed">
    <parent link="world"/>
    <child link="simple_arm_base_link"/>
    <origin rpy="0.0 0.0 0.0" xyz="0.0 0.0 0.0"/>
  </joint>
  <link name="simple_arm_base_link">
    <visual>
      <geometry>
        <mesh filename="ur5_meshes/base.dae"/>
      </geometry>
      <material name="LightGrey">
        <color rgba="0.7 0.7 0.7 1.0"/>
      </material>
    </visual>
    <collision>
      <geometry>
        <mesh filename="ur5_meshes/base.stl"/>
      </geometry>
    </collision>
    <inertial>
      <mass value="4.0"/>
      <origin rpy="0 0 0" xyz="0.0 0.0 0.0"/>
      <inertia ixx="0.00443333156" ixy="0.0" ixz="0.0" iyy="0.00443333156" iyz="0.0" izz="0.0072"/>
    </inertial>
  </link>
  <joint name="simple_arm_shoulder_pan_joint" type="revolute">
    <parent link="simple_arm_base_link"/>
    <child link="simple_arm_shoulder_link"/>
    <origin rpy="0.0 0.0 0.0" xyz="0.0 0.0 0.089159"/>
    <axis xyz="0 0 1"/>
    <limit effort="150.0" lower="-6.28318530718" upper="6.28318530718" velocity="3.15"/>
    <dynamics damping="0.0" friction="0.0"/>
  </joint>
  <link name="simple_arm_shoulder_link">
    <visual>
      <geometry>
        <mesh filename="ur5_meshes/shoulder.dae"/>
      </geometry>
      <material name="LightGrey">
        <color rgba="0.7 0.7 0.7 1.0"/>
      </material>
    </visual>
    <collision>
      <geometry>
        <mesh filename="ur5_meshes/shoulder.stl"/>
      </geometry>
    </collision>
    <inertial>
      <mass value="3.7"/>
      <origin rpy="0 0 0" xyz="0.0 0.0 0.0"/>
      <inertia ixx="0.010267495893" ixy="0.0" ixz="0.0" iyy="0.010267495893" iyz="0.0" izz="0.00666"/>
    </inertial>
  </link>
  <joint name="simple_arm_shoulder_lift_joint" type="revolute">
    <parent link="simple_arm_shoulder_link"/>
    <child link="simple_arm_upper_arm_link"/>
    <origin rpy="0.0 1.57079632679 0.0" xyz="0.0 0.13585 0.0"/>
    <axis xyz="0 1 0"/>
    <limit effort="150.0" lower="-6.28318530718" upper="6.28318530718" velocity="3.15"/>
    <dynamics damping="0.0" friction="0.0"/>
  </joint>
  <link name="simple_arm_upper_arm_link">
    <visual>
      <geometry>
        <mesh filename="ur5_meshes/upperarm.dae"/>
      </geometry>
      <material name="LightGrey">
        <color rgba="0.7 0.7 0.7 1.0"/>
      </material>
    </visual>
    <collision>
      <geometry>
        <mesh filename="ur5_meshes/upperarm.stl"/>
      </geometry>
    </collision>
    <inertial>
      <mass value="8.393"/>
      <origin rpy="0 0 0" xyz="0.0 0.0 0.28"/>
      <inertia ixx="0.22689067591" ixy="0.0" ixz="0.0" iyy="0.22689067591" iyz="0.0" izz="0.0151074"/>
    </inertial>
  </link>
  <joint name="simple_arm_elbow_joint" type="revolute">
    <parent link="simple_arm_upper_arm_link"/>
    <child link="simple_arm_forearm_link"/>
    <origin rpy="0.0 0.0 0.0" xyz="0.0 -0.1197 0.425"/>
    <axis xyz="0 1 0"/>
    <limit effort="150.0" lower="-3.14159265359" upper="3.14159265359" velocity="3.15"/>
    <dynamics damping="0.0" friction="0.0"/>
  </joint>
  <link name="simple_arm_forearm_link">
    <visual>
      <geometry>
        <mesh filename="ur5_meshes/forearm.dae"/>
      </geometry>
      <material name="LightGrey">
        <color rgba="0.7 0.7 0.7 1.0"/>
      </material>
    </visual>
    <collision>
      <geometry>
        <mesh filename="ur5_meshes/forearm.stl"/>
      </geometry>
    </collision>
    <inertial>
      <mass value="2.275"/>
      <origin rpy="0 0 0" xyz="0.0 0.0 0.25"/>
      <inertia ixx="0.049443313556" ixy="0.0" ixz="0.0" iyy="0.049443313556" iyz="0.0" izz="0.004095"/>
    </inertial>
  </link>
  <joint name="simple_arm_wrist_1_joint" type="revolute">
    <parent link="simple_arm_forearm_link"/>
    <child link="simple_arm_wrist_1_link"/>
    <origin rpy="0.0 1.57079632679 0.0" xyz="0.0 0.0 0.39225"/>
    <axis xyz="0 1 0"/>
    <limit effort="28.0" lower="-6.28318530718" upper="6.28318530718" velocity="3.2"/>
    <dynamics damping="0.0" friction="0.0"/>
  </joint>
  <link name="simple_arm_wrist_1_link">
    <visual>
      <geometry>
        <mesh filename="ur5_meshes/wrist1.dae"/>
      </geometry>
      <material name="LightGrey">
        <color rgba="0.7 0.7 0.7 1.0"/>
      </material>
    </visual>
    <collision>
      <geometry>
        <mesh filename="ur5_meshes/wrist1.stl"/>
      </geometry>
    </collision>
    <inertial>
      <mass value="1.219"/>
      <origin rpy="0 0 0" xyz="0.0 0.0 0.0"/>
      <inertia ixx="0.111172755531" ixy="0.0" ixz="0.0" iyy="0.111172755531" iyz="0.0" izz="0.21942"/>
    </inertial>
  </link>
  <joint name="simple_arm_wrist_2_joint" type="revolute">
    <parent link="simple_arm_wrist_1_link"/>
    <child link="simple_arm_wrist_2_link"/>
    <origin rpy="0.0 0.0 0.0" xyz="0.0 0.093 0.0"/>
    <axis xyz="0 0 1"/>
    <limit effort="28.0" lower="-6.28318530718" upper="6.28318530718" velocity="3.2"/>
    <dynamics damping="0.0" friction="0.0"/>
  </joint>
  <link name="simple_arm_wrist_2_link">
    <visual>
      <geometry>
        <mesh filename="ur5_meshes/wrist2.dae"/>
      </geometry>
      <material name="LightGrey">
        <color rgba="0.7 0.7 0.7 1.0"/>
      </material>
    </visual>
    <collision>
      <geometry>
        <mesh filename="ur5_meshes/wrist2.stl"/>
      </geometry>
    </collision>
    <inertial>
      <mass value="1.219"/>
      <origin rpy="0 0 0" xyz="0.0 0.0 0.0"/>
      <inertia ixx="0.111172755531" ixy="0.0" ixz="0.0" iyy="0.111172755531" iyz="0.0" izz="0.21942"/>
    </inertial>
  </link>
  <joint name="simple_arm_wrist_3_joint" type="revolute">
    <parent link="simple_arm_wrist_2_link"/>
    <child link="simple_arm_wrist_3_link"/>
    <origin rpy="0.0 0.0 0.0" xyz="0.0 0.0 0.09465"/>
    <axis xyz="0 1 0"/>
    <limit effort="28.0" lower="-6.28318530718" upper="6.28318530718" velocity="3.2"/>
    <dynamics damping="0.0" friction="0.0"/>
  </joint>
  <link name="simple_arm_wrist_3_link">
    <visual>
      <geometry>
        <mesh filename="ur5_meshes/wrist3.dae"/>
      </geometry>
      <material name="LightGrey">
        <color rgba="0.7 0.7 0.7 1.0"/>
      </material>
    </visual>
    <collision>
      <geometry>
        <mesh filename="ur5_meshes/wrist3.stl"/>
      </geometry>
    </collision>
    <inertial>
      <mass value="0.1879"/>
      <origin rpy="0 0 0" xyz="0.0 0.0 0.0"/>
      <inertia ixx="0.0171364731454" ixy="0.0" ixz="0.0" iyy="0.0171364731454" iyz="0.0" izz="0.033822"/>
    </inertial>
  </link>
  <joint name="simple_arm_ee_fixed_joint" type="fixed">
    <parent link="simple_arm_wrist_3_link"/>
    <child link="simple_arm_ee_link"/>
    <origin rpy="0.0 0.0 1.57079632679" xyz="0.0 0.0823 0.0"/>
  </joint>
  <link name="simple_arm_ee_link">
    <collision>
      <geometry>
        <box size="0.01 0.01 0.01"/>
      </geometry>
      <origin rpy="0 0 0" xyz="-0.01 0 0"/>
    </collision>
    <inertial>
      <mass value="0"/>
      <inertia ixx="0.0" ixy="0.0" ixz="0.0" iyy="0.0" iyz="0.0" izz="0.0"/>
    </inertial>
  </link>
  <transmission name="simple_arm_shoulder_pan_trans">
    <type>transmission_interface/SimpleTransmission</type>
    <joint name="simple_arm_shoulder_pan_joint">
      <hardwareInterface>hardware_interface/PositionJointInterface</hardwareInterface>
    </joint>
    <actuator name="simple_arm_shoulder_pan_motor">
      <mechanicalReduction>1</mechanicalReduction>
    </actuator>
  </transmission>
  <transmission name="simple_arm_shoulder_lift_trans">
    <type>transmission_interface/SimpleTransmission</type>
    <joint name="simple_arm_shoulder_lift_joint">
      <hardwareInterface>hardware_interface/PositionJointInterface</hardwareInterface>
    </joint>
    <actuator name="simple_arm_shoulder_lift_motor">
      <mechanicalReduction>1</mechanicalReduction>
    </actuator>
  </transmission>
  <transmission name="simple_arm_elbow_trans">
    <type>transmission_interface/SimpleTransmission</type>
    <joint name="simple_arm_elbow_joint">
      <hardwareInterface>hardware_interface/PositionJointInterface</hardwareInterface>
    </joint>
    <actuator name="simple_arm_elbow_motor">
      <mechanicalReduction>1</mechanicalReduction>
    </actuator>
  </transmission>
  <transmission name="simple_arm_wrist_1_trans">
    <type>transmission_interface/SimpleTransmission</type>
    <joint name="simple_arm_wrist_1_joint">
      <hardwareInterface>hardware_interface/PositionJointInterface</hardwareInterface>
    </joint>
    <actuator name="simple_arm_wrist_1_motor">
      <mechanicalReduction>1</mechanicalReduction>
    </actuator>
  </transmission>
  <transmission name="simple_arm_wrist_2_trans">
    <type>transmission_interface/SimpleTransmission</type>
    <joint name="simple_arm_wrist_2_joint">
      <hardwareInterface>hardware_interface/PositionJointInterface</hardwareInterface>
    </joint>
    <actuator name="simple_arm_wrist_2_motor">
      <mechanicalReduction>1</mechanicalReduction>
    </actuator>
  </transmission>
  <transmission name="simple_arm_wrist_3_trans">
    <type>transmission_interface/SimpleTransmission</type>
    <joint name="simple_arm_wrist_3_joint">
      <hardwareInterface>hardware_interface/PositionJointInterface</hardwareInterface>
    </joint>
    <actuator name="simple_arm_wrist_3_motor">
      <mechanicalReduction>1</mechanicalReduction>
    </actuator>
  </transmission>
  <!-- nothing to do here at the moment -->
  <!-- ROS base_link to UR 'Base' Coordinates transform -->
  <link name="simple_arm_base">
    <inertial>
      <mass value="0"/>
      <inertia ixx="0.0" ixy="0.0" ixz="0.0" iyy="0.0" iyz="0.0" izz="0.0"/>
    </inertial>
  </link>
  <joint name="simple_arm_base_link-base_fixed_joint" type="fixed">
    <!-- NOTE: this rotation is only needed as long as base_link itself is
                 not corrected wrt the real robot (ie: rotated over 180
                 degrees)
      -->
    <origin rpy="0 0 -3.14159265359" xyz="0 0 0"/>
    <parent link="simple_arm_base_link"/>
    <child link="simple_arm_base"/>
  </joint>
  <!-- Frame coincident with all-zeros TCP on UR controller -->
  <link name="simple_arm_tool0">
    <inertial>
      <mass value="0"/>
      <inertia ixx="0.0" ixy="0.0" ixz="0.0" iyy="0.0" iyz="0.0" izz="0.0"/>
    </inertial>
  </link>
  <joint name="simple_arm_wrist_3_link-tool0_fixed_joint" type="fixed">
    <origin rpy="-1.57079632679 0 0" xyz="0 0.0823 0"/>
    <parent link="simple_arm_wrist_3_link"/>
    <child link="simple_arm_tool0"/>
  </joint>
  <!-- base -->
  <joint name="simple_arm_tool0_simple_gripper_base_joint" type="fixed">
    <origin rpy="0 -1.5708 0" xyz="0 0 0"/>
    <parent link="simple_arm_tool0"/>
    <child link="robotiq_85_base_link"/>
  </joint>

  <!-- robot -->
    <link name="robotiq_85_base_link">
      <visual>
        <geometry>
          <mesh filename="../meshes/visual/robotiq_85_base_link.dae"/>
        </geometry>
      </visual>
      <collision>
        <geometry>
          <mesh filename="../meshes/collision/robotiq_85_base_link.stl"/>
        </geometry>
      </collision>
      <inertial>
        <mass value="0.636951" />
        <origin xyz="0.0 0.0 0.0" />
        <inertia ixx = "0.000380" ixy = "0.000000" ixz = "0.000000"
             iyx = "0.000000" iyy = "0.001110" iyz = "0.000000"
             izx = "0.000000" izy = "0.000000" izz = "0.001171" />
      </inertial>
    </link>

    <joint name="robotiq_85_left_knuckle_joint" type="revolute">
      <parent link="robotiq_85_base_link"/>
      <child link="robotiq_85_left_knuckle_link"/>
      <axis xyz="0 0 1"/>
      <origin rpy="3.14 0.0 0.0" xyz="0.05490451627 0.03060114443 0.0"/>
      <limit lower="0.0" upper="0.80285" velocity="3.14" effort="1000"/>
    </joint>

    <joint name="robotiq_85_right_knuckle_joint" type="revolute">
      <parent link="robotiq_85_base_link"/>
      <child link="robotiq_85_right_knuckle_link"/>
      <axis xyz="0 0 1"/>
      <origin rpy="0.0 0.0 0.0" xyz="0.05490451627 -0.03060114443 0.0"/>
      <limit lower="-3.14" upper="3.14" velocity="3.14" effort="1000"/>
      <mimic joint="robotiq_85_left_knuckle_joint"/>
    </joint>

    <link name="robotiq_85_left_knuckle_link">
      <visual>
        <geometry>
          <mesh filename="../meshes/visual/robotiq_85_knuckle_link.dae"/>
        </geometry>
      </visual>
      <collision>
        <geometry>
          <mesh filename="../meshes/collision/robotiq_85_knuckle_link.stl"/>
        </geometry>
      </collision>
      <inertial>
        <mass value="0.18491" />
        <origin xyz="0.0 0.0 0.0" />
        <inertia ixx = "0.000009" ixy = "-0.000001" ixz = "0.000000"
             iyx = "-0.000001" iyy = "0.000001" iyz = "0.000000"
             izx = "0.000000" izy = "0.000000" izz = "0.000010" />
      </inertial>
    </link>

    <link name="robotiq_85_right_knuckle_link">
      <visual>
        <geometry>
          <mesh filename="../meshes/visual/robotiq_85_knuckle_link.dae"/>
        </geometry>
      </visual>
      <collision>
        <geometry>
          <mesh filename="../meshes/collision/robotiq_85_knuckle_link.stl"/>
        </geometry>
      </collision>
      <inertial>
        <mass value="0.18491" />
        <origin xyz="0.0 0.0 0.0" />
        <inertia ixx = "0.000009" ixy = "-0.000001" ixz = "0.000000"
             iyx = "-0.000001" iyy = "0.000001" iyz = "0.000000"
             izx = "0.000000" izy = "0.000000" izz = "0.000010" />
      </inertial>
    </link>

    <joint name="robotiq_85_left_finger_joint" type="fixed">
      <parent link="robotiq_85_left_knuckle_link"/>
      <child link="robotiq_85_left_finger_link"/>
      <origin xyz="-0.00408552455 -0.03148604435 0.0" rpy="0 0 0" />
    </joint>

    <joint name="robotiq_85_right_finger_joint" type="fixed">
      <parent link="robotiq_85_right_knuckle_link"/>
      <child link="robotiq_85_right_finger_link"/>
      <origin xyz="-0.00408552455 -0.03148604435 0.0" rpy="0 0 0" />
    </joint>

    <link name="robotiq_85_left_finger_link">
      <visual>
        <geometry>
          <mesh filename="../meshes/visual/robotiq_85_finger_link.dae"/>
        </geometry>
      </visual>
      <collision>
        <geometry>
          <mesh filename="../meshes/collision/robotiq_85_finger_link.stl"/>
        </geometry>
      </collision>
      <inertial>
        <mass value="0.27309" />
        <origin xyz="0.0 0.0 0.0" />
        <inertia ixx = "0.000003" ixy = "-0.000002" ixz = "0.000000"
             iyx = "-0.000002" iyy = "0.000021" iyz = "0.000000"
             izx = "0.000000" izy = "0.000000" izz = "0.000020" />
      </inertial>
    </link>

    <link name="robotiq_85_right_finger_link">
      <visual>
        <geometry>
          <mesh filename="../meshes/visual/robotiq_85_finger_link.dae"/>
        </geometry>
      </visual>
      <collision>
        <geometry>
          <mesh filename="../meshes/collision/robotiq_85_finger_link.stl"/>
        </geometry>
      </collision>
      <inertial>
        <mass value="0.27309" />
        <origin xyz="0.0 0.0 0.0" />
        <inertia ixx = "0.000003" ixy = "-0.000002" ixz = "0.000000"
             iyx = "-0.000002" iyy = "0.000021" iyz = "0.000000"
             izx = "0.000000" izy = "0.000000" izz = "0.000020" />
      </inertial>
    </link>

    <joint name="robotiq_85_left_inner_knuckle_joint" type="revolute">
      <parent link="robotiq_85_base_link"/>
      <child link="robotiq_85_left_inner_knuckle_link"/>
      <axis xyz="0 0 1"/>
      <origin xyz="0.06142 0.0127 0" rpy="3.14 0.0 0.0" />
      <limit lower="-3.14" upper="3.14" velocity="3.14" effort="60"/>
      <mimic joint="robotiq_85_left_knuckle_joint" offset="0"/>
    </joint>

    <joint name="robotiq_85_right_inner_knuckle_joint" type="revolute">
      <parent link="robotiq_85_base_link"/>
      <child link="robotiq_85_right_inner_knuckle_link"/>
      <axis xyz="0 0 1"/>
      <origin xyz="0.06142 -0.0127 0" rpy="0 0 0"/>
      <limit lower="-3.14" upper="3.14" velocity="3.14" effort="60"/>
      <mimic joint="robotiq_85_left_knuckle_joint" offset="0"/>
    </joint>

    <link name="robotiq_85_left_inner_knuckle_link">
      <visual>
        <geometry>
          <mesh filename="../meshes/visual/robotiq_85_inner_knuckle_link.dae"/>
        </geometry>
      </visual>
      <collision>
        <geometry>
          <mesh filename="../meshes/collision/robotiq_85_inner_knuckle_link.stl"/>
        </geometry>
      </collision>
      <inertial>
        <mass value="0.29951" />
        <origin xyz="0.0 0.0 0.0" />
        <inertia ixx = "0.000039" ixy = "0.000000" ixz = "0.000000"
             iyx = "0.000000" iyy = "0.000005" iyz = "0.000000"
             izx = "0.000000" izy = "0.000000" izz = "0.000035" />
      </inertial>
    </link>
    <link name="robotiq_85_right_inner_knuckle_link">
      <visual>
        <geometry>
          <mesh filename="../meshes/visual/robotiq_85_inner_knuckle_link.dae"/>
        </geometry>
      </visual>
      <collision>
        <geometry>
          <mesh filename="../meshes/collision/robotiq_85_inner_knuckle_link.stl"/>
        </geometry>
      </collision>
      <inertial>
        <mass value="0.29951" />
        <origin xyz="0.0 0.0 0.0" />
        <inertia ixx = "0.000039" ixy = "0.000000" ixz = "0.000000"
             iyx = "0.000000" iyy = "0.000005" iyz = "0.000000"
             izx = "0.000000" izy = "0.000000" izz = "0.000035" />
      </inertial>
    </link>

    <joint name="robotiq_85_left_finger_tip_joint" type="revolute">
      <parent link="robotiq_85_left_inner_knuckle_link"/>
      <child link="robotiq_85_left_finger_tip_link"/>
      <axis xyz="0 0 1"/>
      <!--<origin xyz="0.04303959807 -0.03759940821 0.0" rpy="0.0 0.0 0.0"/>-->
      <origin rpy="0.0 0.0 0.0" xyz="0.064 -0.03759940821  0.0"/>
      <limit lower="-3.14" upper="3.14" velocity="0.02" effort="60"/>
      <mimic joint="robotiq_85_left_knuckle_joint" multiplier="-1"/>
    </joint>

    <joint name="robotiq_85_right_finger_tip_joint" type="revolute">
      <parent link="robotiq_85_right_inner_knuckle_link"/>
      <child link="robotiq_85_right_finger_tip_link"/>
      <axis xyz="0 0 1"/>
      <!--<origin rpy="0.0 0.0 0.0" xyz="0.04303959807 -0.03759940821  0.0"/>-->
      <origin rpy="0.0 0.0 0.0" xyz="0.064 -0.03759940821  0.0"/>
      <limit lower="-3.14" upper="3.14" velocity="0.02" effort="60"/>
      <mimic joint="robotiq_85_left_knuckle_joint" multiplier="-1"/>
    </joint>


    <link name="robotiq_85_left_finger_tip_link">
      <!--<visual>-->
        <!--<geometry>-->
          <!--<mesh filename="../meshes/visual/robotiq_85_finger_tip_link.dae"/>-->
        <!--</geometry>-->
      <!--</visual>-->
      <!--<collision>-->
        <!--<geometry>-->
          <!--<mesh filename="../meshes/collision/robotiq_85_finger_tip_link.stl"/>-->
        <!--</geometry>-->
      <!--</collision>-->
      <visual>
        <geometry>
          <box size="0.05 0.005 0.025 "/>
        </geometry>
      </visual>
      <collision>
        <origin rpy="0 0 0" xyz="0 0 0.0"/>
        <geometry>
          <box size="0.05 0.005 0.025 "/>
        </geometry>
      </collision>
      <inertial>
        <mass value="1" />
        <origin xyz="0.0 0.0 0.0" />
        <inertia ixx="1.0" ixy="0.0" ixz="0.0" iyy="1.0" iyz="0.0" izz="1.0"/>

      </inertial>
      <contact>
      <lateral_friction value="20"/>
      <spinning_friction value="0.0"/>
      <rolling_friction value="0.0"/>
    </contact>
    </link>

    <link name="robotiq_85_right_finger_tip_link">
      <!--<visual>-->
        <!--<geometry>-->
          <!--<mesh filename="../meshes/visual/robotiq_85_finger_tip_link.dae"/>-->
        <!--</geometry>-->
      <!--</visual>-->
      <!--<collision>-->
        <!--<geometry>-->
          <!--<mesh filename="../meshes/collision/robotiq_85_finger_tip_link.stl"/>-->
        <!--</geometry>-->
      <!--</collision>-->
      <visual>
        <geometry>
          <box size="0.05 0.005 0.025 "/>
        </geometry>
      </visual>
      <collision>
        <origin rpy="0 0 0" xyz="0 0 0.0"/>
        <geometry>
          <box size="0.05 0.005 0.025 "/>
        </geometry>
      </collision>
      <inertial>
        <mass value="1" />
        <origin xyz="0.0 0.0 0.0" />
        <inertia ixx="1.0" ixy="0.0" ixz="0.0" iyy="1.0" iyz="0.0" izz="1.0"/>

      </inertial>
      <contact>
      <lateral_friction value="20"/>
      <spinning_friction value="0.0"/>
      <rolling_friction value="0.0"/>
    </contact>
    </link>

   <link name="dummy_center_indicator_link">
    <!--<visual>-->
      <!--<geometry>-->
        <!--<box size="0.020 0.085 0.002"/>-->
      <!--</geometry>-->
    <!--</visual>-->
    <inertial>
      <mass value="0.0" />
      <inertia ixx = "0" ixy = "0" ixz = "0"
               iyx = "0" iyy = "0" iyz = "0"
               izx = "0" izy = "0" izz = "0" />
    </inertial>
  </link>

  <joint name="dummy_center_fixed_joint" type="fixed">
    <child link="dummy_center_indicator_link"/>
    <parent link="simple_arm_tool0"/>
    <origin rpy="0.0 0.0 1.5707" xyz="0 0 0.14" />
  </joint>
</robot>
